Workbook
Name Slicer_Item: #N/A
Name Slicer_Payment_Method: #N/A
Name Slicer_Transaction_Date: #N/A

Sheet Pivot_table
A3: Sum of Final_Total | D3: Sum of Final_Quantity | G3: Count of Transaction ID | I3: Distinct Count of Item | K3: Average of Price Per Unit
A4: 80491 | D4: 27243 | G4: 8996 | I4: 8 | K4: 2.9498666
A7: Row Labels | B7: Sum of Final_Total | D7: Row Labels | E7: Sum of Final_Total | G7: Row Labels | H7: Count of Final_Total | L7: =A4/G4 -> 8.9474211
A8: Cookie | B8: 3228 | D8: Cash | E8: 18513 | G8: January | H8: 740
A9: Tea | B9: 4938 | D9: Credit Card | E9: 18412.5 | G9: February | H9: 648
A10: Coffee | B10: 7068 | D10: Digital Wallet | E10: 18321 | G10: March | H10: 740
A11: Cake | B11: 10386 | D11: N/A | E11: 25244.5 | G11: April | H11: 696
A12: Juice | B12: 10515 | D12: Grand Total | E12: 80491 | G12: May | H12: 695
A13: Smoothie | B13: 13320 | G13: June | H13: 733
A14: Sandwich | B14: 13696 | G14: July | H14: 716
A15: Salad | B15: 17340 | G15: August | H15: 714
A16: Grand Total | B16: 80491 | G16: September | H16: 705
G17: October | H17: 765
G18: November | H18: 720
A19: Row Labels | B19: Sum of Final_Quantity | D19: Row Labels | E19: Sum of Final_Total | G19: December | H19: 708
A20: Cookie | B20: 3228 | D20: In-store | E20: 24677 | G20: Unknown | H20: 416
A21: Tea | B21: 3292 | D21: N/A | E21: 31958 | G21: Grand Total | H21: 8996
A22: Smoothie | B22: 3330 | D22: Takeaway | E22: 23856
A23: Sandwich | B23: 3424 | D23: Grand Total | E23: 80491
A24: Cake | B24: 3462 | G24: Row Labels | H24: Sum of Final_Quantity | I24: Sum of Final_Total
A25: Salad | B25: 3468 | G25: Cake | H25: 3462 | I25: 10386
A26: Juice | B26: 3505 | D26: Row Labels | E26: Sum of Final_Price | G26: Cookie | H26: 3228 | I26: 3228
A27: Coffee | B27: 3534 | D27: Sunday | E27: 3737 | G27: Juice | H27: 3505 | I27: 10515
A28: Grand Total | B28: 27243 | D28: Monday | E28: 3638 | G28: Salad | H28: 3468 | I28: 17340
D29: Tuesday | E29: 3501.5 | G29: Sandwich | H29: 3424 | I29: 13696
D30: Wednesday | E30: 3512 | G30: Smoothie | H30: 3330 | I30: 13320
D31: Thursday | E31: 3682.5 | G31: Tea | H31: 3292 | I31: 4938
D32: Friday | E32: 3685.5 | G32: Coffee | H32: 3534 | I32: 7068
D33: Saturday | E33: 3576 | G33: Grand Total | H33: 27243 | I33: 80491
D34: Unknown | E34: 1204.5
D35: Grand Total | E35: 26537

Sheet Dashboard

Sheet cleaned_data
A1: Transaction ID | B1: Item | C1: Quantity | D1: Final_Quantity | E1: Price Per Unit | F1: Final_Price | G1: Total Spent | H1: Final_Total | I1: Payment Method | J1: Location | K1: Transaction Date | L1: Month Name | M1: Day of Week | N1: Missing_Flag | O1: Quantity_Sourced
A2: TXN_1961373 | B2: Coffee | C2: 2 | D2: =IF(OR(C2="",C2="UNKNOWN",C2="ERROR"),IFERROR(VALUE(G2)/VALUE(E2),""),VALUE(C2)) -> 2 | E2: 2 | F2: =IF(OR(E2="",E2="UNKNOWN",E2="ERROR"),_xlfn.XLOOKUP(Table2[[#This Row],[Item]],Items_List!A:A,Items_List!B:B),E2) -> 2 | G2: 4 | H2: =D2*F2 -> 4 | I2: Credit Card | J2: Takeaway | K2: 45177 | L2: =IF(ISNUMBER(Table2[[#This Row],[Transaction Date]]),TEXT(Table2[[#This Row],[Transaction Date]],"mmmm"),"Unknown") -> September | M2: =IF(ISNUMBER(Table2[[#This Row],[Transaction Date]]),TEXT(Table2[[#This Row],[Transaction Date]],"dddd"),"Unknown") -> Friday | N2: =IF(OR(B2="",B2="unknown",B2="error",C2="",C2="unknown",C2="error",G2="",G2="error",G2="unknown"),1,0) -> 0 | O2: =IF(OR(C2="",C2="error",C2="unknown"),"Estimated","Actual") -> Actual
A3: TXN_4977031 | B3: Cake | C3: 4 | D3: =IF(OR(C3="",C3="UNKNOWN",C3="ERROR"),IFERROR(VALUE(G3)/VALUE(E3),""),VALUE(C3)) -> 4 | E3: 3 | F3: =IF(OR(E3="",E3="UNKNOWN",E3="ERROR"),_xlfn.XLOOKUP(Table2[[#This Row],[Item]],Items_List!A:A,Items_List!B:B),E3) -> 3 | G3: 12 | H3: =D3*F3 -> 12 | I3: Cash | J3: In-store | K3: 45062 | L3: =IF(ISNUMBER(Table2[[#This Row],[Transaction Date]]),TEXT(Table2[[#This Row],[Transaction Date]],"mmmm"),"Unknown") -> May | M3: =IF(ISNUMBER(Table2[[#This Row],[Transaction Date]]),TEXT(Table2[[#This Row],[Transaction Date]],"dddd"),"Unknown") -> Tuesday | N3: =IF(OR(B3="",B3="unknown",B3="error",C3="",C3="unknown",C3="error",G3="",G3="error",G3="unknown"),1,0) -> 0 | O3: =IF(OR(C3="",C3="error",C3="unknown"),"Estimated","Actual") -> Actual
A4: TXN_4271903 | B4: Cookie | C4: 4 | D4: =IF(OR(C4="",C4="UNKNOWN",C4="ERROR"),IFERROR(VALUE(G4)/VALUE(E4),""),VALUE(C4)) -> 4 | E4: 1 | F4: =IF(OR(E4="",E4="UNKNOWN",E4="ERROR"),_xlfn.XLOOKUP(Table2[[#This Row],[Item]],Items_List!A:A,Items_List!B:B),E4) -> 1 | G4: ERROR | H4: =D4*F4 -> 4 | I4: Credit Card | J4: In-store | K4: 45126 | L4: =IF(ISNUMBER(Table2[[#This Row],[Transaction Date]]),TEXT(Table2[[#This Row],[Transaction Date]],"mmmm"),"Unknown") -> July | M4: =IF(ISNUMBER(Table2[[#This Row],[Transaction Date]]),TEXT(Table2[[#This Row],[Transaction Date]],"dddd"),"Unknown") -> Wednesday | N4: =IF(OR(B4="",B4="unknown",B4="error",C4="",C4="unknown",C4="error",G4="",G4="error",G4="unknown"),1,0) -> 1 | O4: =IF(OR(C4="",C4="error",C4="unknown"),"Estimated","Actual") -> Actual
A5: TXN_7034554 | B5: Salad | C5: 2 | D5: =IF(OR(C5="",C5="UNKNOWN",C5="ERROR"),IFERROR(VALUE(G5)/VALUE(E5),""),VALUE(C5)) -> 2 | E5: 5 | F5: =IF(OR(E5="",E5="UNKNOWN",E5="ERROR"),_xlfn.XLOOKUP(Table2[[#This Row],[Item]],Items_List!A:A,Items_List!B:B),E5) -> 5 | G5: 10 | H5: =D5*F5 -> 10 | I5: N/A | J5: N/A | K5: 45043 | L5: =IF(ISNUMBER(Table2[[#This Row],[Transaction Date]]),TEXT(Table2[[#This Row],[Transaction Date]],"mmmm"),"Unknown") -> April | M5: =IF(ISNUMBER(Table2[[#This Row],[Transaction Date]]),TEXT(Table2[[#This Row],[Transaction Date]],"dddd"),"Unknown") -> Thursday | N5: =IF(OR(B5="",B5="unknown",B5="error",C5="",C5="unknown",C5="error",G5="",G5="error",G5="unknown"),1,0) -> 0 | O5: =IF(OR(C5="",C5="error",C5="unknown"),"Estimated","Actual") -> Actual
A6: TXN_3160411 | B6: Coffee | C6: 2 | D6: =IF(OR(C6="",C6="UNKNOWN",C6="ERROR"),IFERROR(VALUE(G6)/VALUE(E6),""),VALUE(C6)) -> 2 | E6: 2 | F6: =IF(OR(E6="",E6="UNKNOWN",E6="ERROR"),_xlfn.XLOOKUP(Table2[[#This Row],[Item]],Items_List!A:A,Items_List!B:B),E6) -> 2 | G6: 4 | H6: =D6*F6 -> 4 | I6: Digital Wallet | J6: In-store | K6: 45088 | L6: =IF(ISNUMBER(Table2[[#This Row],[Transaction Date]]),TEXT(Table2[[#This Row],[Transaction Date]],"mmmm"),"Unknown") -> June | M6: =IF(ISNUMBER(Table2[[#This Row],[Transaction Date]]),TEXT(Table2[[#This Row],[Transaction Date]],"dddd"),"Unknown") -> Sunday | N6: =IF(OR(B6="",B6="unknown",B6="error",C6="",C6="unknown",C6="error",G6="",G6="error",G6="unknown"),1,0) -> 0 | O6: =IF(OR(C6="",C6="error",C6="unknown"),"Estimated","Actual") -> Actual
A7: TXN_2602893 | B7: Smoothie | C7: 5 | D7: =IF(OR(C7="",C7="UNKNOWN",C7="ERROR"),IFERROR(VALUE(G7)/VALUE(E7),""),VALUE(C7)) -> 5 | E7: 4 | F7: =IF(OR(E7="",E7="UNKNOWN",E7="ERROR"),_xlfn.XLOOKUP(Table2[[#This Row],[Item]],Items_List!A:A,Items_List!B:B),E7) -> 4 | G7: 20 | H7: =D7*F7 -> 20 | I7: Credit Card | J7: N/A | K7: 45016 | L7: =IF(ISNUMBER(Table2[[#This Row],[Transaction Date]]),TEXT(Table2[[#This Row],[Transaction Date]],"mmmm"),"Unknown") -> March | M7: =IF(ISNUMBER(Table2[[#This Row],[Transaction Date]]),TEXT(Table2[[#This Row],[Transaction Date]],"dddd"),"Unknown") -> Friday | N7: =IF(OR(B7="",B7="unknown",B7="error",C7="",C7="unknown",C7="error",G7="",G7="error",G7="unknown"),1,0) -> 0 | O7: =IF(OR(C7="",C7="error",C7="unknown"),"Estimated","Actual") -> Actual | P7: 1
A8: TXN_6699534 | B8: Sandwich | C8: 4 | D8: =IF(OR(C8="",C8="UNKNOWN",C8="ERROR"),IFERROR(VALUE(G8)/VALUE(E8),""),VALUE(C8)) -> 4 | E8: 4 | F8: =IF(OR(E8="",E8="UNKNOWN",E8="ERROR"),_xlfn.XLOOKUP(Table2[[#This Row],[Item]],Items_List!A:A,Items_List!B:B),E8) -> 4 | G8: 16 | H8: =D8*F8 -> 16 | I8: Cash | J8: N/A | K8: 45227 | L8: =IF(ISNUMBER(Table2[[#This Row],[Transaction Date]]),TEXT(Table2[[#This Row],[Transaction Date]],"mmmm"),"Unknown") -> October | M8: =IF(ISNUMBER(Table2[[#This Row],[Transaction Date]]),TEXT(Table2[[#This Row],[Transaction Date]],"dddd"),"Unknown") -> Saturday | N8: =IF(OR(B8="",B8="unknown",B8="error",C8="",C8="unknown",C8="error",G8="",G8="error",G8="unknown"),1,0) -> 0 | O8: =IF(OR(C8="",C8="error",C8="unknown"),"Estimated","Actual") -> Actual
A9: TXN_2064365 | B9: Sandwich | C9: 5 | D9: =IF(OR(C9="",C9="UNKNOWN",C9="ERROR"),IFERROR(VALUE(G9)/VALUE(E9),""),VALUE(C9)) -> 5 | E9: 4 | F9: =IF(OR(E9="",E9="UNKNOWN",E9="ERROR"),_xlfn.XLOOKUP(Table2[[#This Row],[Item]],Items_List!A:A,Items_List!B:B),E9) -> 4 | G9: 20 | H9: =D9*F9 -> 20 | I9: N/A | J9: In-store | K9: 45291 | L9: =IF(ISNUMBER(Table2[[#This Row],[Transaction Date]]),TEXT(Table2[[#This Row],[Transaction Date]],"mmmm"),"Unknown") -> December | M9: =IF(ISNUMBER(Table2[[#This Row],[Transaction Date]]),TEXT(Table2[[#This Row],[Transaction Date]],"dddd"),"Unknown") -> Sunday | N9: =IF(OR(B9="",B9="unknown",B9="error",C9="",C9="unknown",C9="error",G9="",G9="error",G9="unknown"),1,0) -> 0 | O9: =IF(OR(C9="",C9="error",C9="unknown"),"Estimated","Actual") -> Actual
A10: TXN_2548360 | B10: Salad | C10: 5 | D10: =IF(OR(C10="",C10="UNKNOWN",C10="ERROR"),IFERROR(VALUE(G10)/VALUE(E10),""),VALUE(C10)) -> 5 | E10: 5 | F10: =IF(OR(E10="",E10="UNKNOWN",E10="ERROR"),_xlfn.XLOOKUP(Table2[[#This Row],[Item]],Items_List!A:A,Items_List!B:B),E10) -> 5 | G10: 25 | H10: =D10*F10 -> 25 | I10: Cash | J10: Takeaway | K10: 45237 | L10: =IF(ISNUMBER(Table2[[#This Row],[Transaction Date]]),TEXT(Table2[[#This Row],[Transaction Date]],"mmmm"),"Unknown") -> November | M10: =IF(ISNUMBER(Table2[[#This Row],[Transaction Date]]),TEXT(Table2[[#This Row],[Transaction Date]],"dddd"),"Unknown") -> Tuesday | N10: =IF(OR(B10="",B10="unknown",B10="error",C10="",C10="unknown",C10="error",G10="",G10="error",G10="unknown"),1,0) -> 0 | O10: =IF(OR(C10="",C10="error",C10="unknown"),"Estimated","Actual") -> Actual
A11: TXN_3051279 | B11: Sandwich | C11: 2 | D11: =IF(OR(C11="",C11="UNKNOWN",C11="ERROR"),IFERROR(VALUE(G11)/VALUE(E11),""),VALUE(C11)) -> 2 | E11: 4 | F11: =IF(OR(E11="",E11="UNKNOWN",E11="ERROR"),_xlfn.XLOOKUP(Table2[[#This Row],[Item]],Items_List!A:A,Items_List!B:B),E11) -> 4 | G11: 8 | H11: =D11*F11 -> 8 | I11: Credit Card | J11: Takeaway | L11: =IF(ISNUMBER(Table2[[#This Row],[Transaction Date]]),TEXT(Table2[[#This Row],[Transaction Date]],"mmmm"),"Unknown") -> Unknown | M11: =IF(ISNUMBER(Table2[[#This Row],[Transaction Date]]),TEXT(Table2[[#This Row],[Transaction Date]],"dddd"),"Unknown") -> Unknown | N11: =IF(OR(B11="",B11="unknown",B11="error",C11="",C11="unknown",C11="error",G11="",G11="error",G11="unknown"),1,0) -> 0 | O11: =IF(OR(C11="",C11="error",C11="unknown"),"Estimated","Actual") -> Actual
A12: TXN_7619095 | B12: Sandwich | C12: 2 | D12: =IF(OR(C12="",C12="UNKNOWN",C12="ERROR"),IFERROR(VALUE(G12)/VALUE(E12),""),VALUE(C12)) -> 2 | E12: 4 | F12: =IF(OR(E12="",E12="UNKNOWN",E12="ERROR"),_xlfn.XLOOKUP(Table2[[#This Row],[Item]],Items_List!A:A,Items_List!B:B),E12) -> 4 | G12: 8 | H12: =D12*F12 -> 8 | I12: Cash | J12: In-store | K12: 45049 | L12: =IF(ISNUMBER(Table2[[#This Row],[Transaction Date]]),TEXT(Table2[[#This Row],[Transaction Date]],"mmmm"),"Unknown") -> May | M12: =IF(ISNUMBER(Table2[[#This Row],[Transaction Date]]),TEXT(Table2[[#This Row],[Transaction Date]],"dddd"),"Unknown") -> Wednesday | N12: =IF(OR(B12="",B12="unknown",B12="error",C12="",C12="unknown",C12="error",G12="",G12="error",G12="unknown"),1,0) -> 0 | O12: =IF(OR(C12="",C12="error",C12="unknown"),"Estimated","Actual") -> Actual
A13: TXN_9437049 | B13: Cookie | C13: 5 | D13: =IF(OR(C13="",C13="UNKNOWN",C13="ERROR"),IFERROR(VALUE(G13)/VALUE(E13),""),VALUE(C13)) -> 5 | E13: 1 | F13: =IF(OR(E13="",E13="UNKNOWN",E13="ERROR"),_xlfn.XLOOKUP(Table2[[#This Row],[Item]],Items_List!A:A,Items_List!B:B),E13) -> 1 | G13: 5 | H13: =D13*F13 -> 5 | I13: N/A | J13: Takeaway | K13: 45078 | L13: =IF(ISNUMBER(Table2[[#This Row],[Transaction Date]]),TEXT(Table2[[#This Row],[Transaction Date]],"mmmm"),"Unknown") -> June | M13: =IF(ISNUMBER(Table2[[#This Row],[Transaction Date]]),TEXT(Table2[[#This Row],[Transaction Date]],"dddd"),"Unknown") -> Thursday | N13: =IF(OR(B13="",B13="unknown",B13="error",C13="",C13="unknown",C13="error",G13="",G13="error",G13="unknown"),1,0) -> 0 | O13: =IF(OR(C13="",C13="error",C13="unknown"),"Estimated","Actual") -> Actual
A14: TXN_2847255 | B14: Salad | C14: 3 | D14: =IF(OR(C14="",C14="UNKNOWN",C14="ERROR"),IFERROR(VALUE(G14)/VALUE(E14),""),VALUE(C14)) -> 3 | E14: 5 | F14: =IF(OR(E14="",E14="UNKNOWN",E14="ERROR"),_xlfn.XLOOKUP(Table2[[#This Row],[Item]],Items_List!A:A,Items_List!B:B),E14) -> 5 | G14: 15 | H14: =D14*F14 -> 15 | I14: Credit Card | J14: In-store | K14: 45245 | L14: =IF(ISNUMBER(Table2[[#This Row],[Transaction Date]]),TEXT(Table2[[#This Row],[Transaction Date]],"mmmm"),"Unknown") -> November | M14: =IF(ISNUMBER(Table2[[#This Row],[Transaction Date]]),TEXT(Table2[[#This Row],[Transaction Date]],"dddd"),"Unknown") -> Wednesday | N14: =IF(OR(B14="",B14="unknown",B14="error",C14="",C14="unknown",C14="error",G14="",G14="error",G14="unknown"),1,0) -> 0 | O14: =IF(OR(C14="",C14="error",C14="unknown"),"Estimated","Actual") -> Actual
A15: TXN_3765707 | B15: Sandwich | C15: 1 | D15: =IF(OR(C15="",C15="UNKNOWN",C15="ERROR"),IFERROR(VALUE(G15)/VALUE(E15),""),VALUE(C15)) -> 1 | E15: 4 | F15: =IF(OR(E15="",E15="UNKNOWN",E15="ERROR"),_xlfn.XLOOKUP(Table2[[#This Row],[Item]],Items_List!A:A,Items_List!B:B),E15) -> 4 | G15: 4 | H15: =D15*F15 -> 4 | I15: N/A | J15: N/A | K15: 45087 | L15: =IF(ISNUMBER(Table2[[#This Row],[Transaction Date]]),TEXT(Table2[[#This Row],[Transaction Date]],"mmmm"),"Unknown") -> June | M15: =IF(ISNUMBER(Table2[[#This Row],[Transaction Date]]),TEXT(Table2[[#This Row],[Transaction Date]],"dddd"),"Unknown") -> Saturday | N15: =IF(OR(B15="",B15="unknown",B15="error",C15="",C15="unknown",C15="error",G15="",G15="error",G15="unknown"),1,0) -> 0 | O15: =IF(OR(C15="",C15="error",C15="unknown"),"Estimated","Actual") -> Actual
A16: TXN_6769710 | B16: Juice | C16: 2 | D16: =IF(OR(C16="",C16="UNKNOWN",C16="ERROR"),IFERROR(VALUE(G16)/VALUE(E16),""),VALUE(C16)) -> 2 | E16: 3 | F16: =IF(OR(E16="",E16="UNKNOWN",E16="ERROR"),_xlfn.XLOOKUP(Table2[[#This Row],[Item]],Items_List!A:A,Items_List!B:B),E16) -> 3 | G16: 6 | H16: =D16*F16 -> 6 | I16: Cash | J16: In-store | K16: 44981 | L16: =IF(ISNUMBER(Table2[[#This Row],[Transaction Date]]),TEXT(Table2[[#This Row],[Transaction Date]],"mmmm"),"Unknown") -> February | M16: =IF(ISNUMBER(Table2[[#This Row],[Transaction Date]]),TEXT(Table2[[#This Row],[Transaction Date]],"dddd"),"Unknown") -> Friday | N16: =IF(OR(B16="",B16="unknown",B16="error",C16="",C16="unknown",C16="error",G16="",G16="error",G16="unknown"),1,0) -> 0 | O16: =IF(OR(C16="",C16="error",C16="unknown"),"Estimated","Actual") -> Actual
A17: TXN_8876618 | B17: Cake | C17: 5 | D17: =IF(OR(C17="",C17="UNKNOWN",C17="ERROR"),IFERROR(VALUE(G17)/VALUE(E17),""),VALUE(C17)) -> 5 | E17: 3 | F17: =IF(OR(E17="",E17="UNKNOWN",E17="ERROR"),_xlfn.XLOOKUP(Table2[[#This Row],[Item]],Items_List!A:A,Items_List!B:B),E17) -> 3 | G17: 15 | H17: =D17*F17 -> 15 | I17: Cash | J17: N/A | K17: 45010 | L17: =IF(ISNUMBER(Table2[[#This Row],[Transaction Date]]),TEXT(Table2[[#This Row],[Transaction Date]],"mmmm"),"Unknown") -> March | M17: =IF(ISNUMBER(Table2[[#This Row],[Transaction Date]]),TEXT(Table2[[#This Row],[Transaction Date]],"dddd"),"Unknown") -> Saturday | N17: =IF(OR(B17="",B17="unknown",B17="error",C17="",C17="unknown",C17="error",G17="",G17="error",G17="unknown"),1,0) -> 0 | O17: =IF(OR(C17="",C17="error",C17="unknown"),"Estimated","Actual") -> Actual
A18: TXN_3709394 | B18: Juice | C18: 4 | D18: =IF(OR(C18="",C18="UNKNOWN",C18="ERROR"),IFERROR(VALUE(G18)/VALUE(E18),""),VALUE(C18)) -> 4 | E18: 3 | F18: =IF(OR(E18="",E18="UNKNOWN",E18="ERROR"),_xlfn.XLOOKUP(Table2[[#This Row],[Item]],Items_List!A:A,Items_List!B:B),E18) -> 3 | G18: 12 | H18: =D18*F18 -> 12 | I18: Cash | J18: Takeaway | K18: 44941 | L18: =IF(ISNUMBER(Table2[[#This Row],[Transaction Date]]),TEXT(Table2[[#This Row],[Transaction Date]],"mmmm"),"Unknown") -> January | M18: =IF(ISNUMBER(Table2[[#This Row],[Transaction Date]]),TEXT(Table2[[#This Row],[Transaction Date]],"dddd"),"Unknown") -> Sunday | N18: =IF(OR(B18="",B18="unknown",B18="error",C18="",C18="unknown",C18="error",G18="",G18="error",G18="unknown"),1,0) -> 0 | O18: =IF(OR(C18="",C18="error",C18="unknown"),"Estimated","Actual") -> Actual
A19: TXN_3522028 | B19: Smoothie | C19: ERROR | D19: =IF(OR(C19="",C19="UNKNOWN",C19="ERROR"),IFERROR(VALUE(G19)/VALUE(E19),""),VALUE(C19)) -> 5 | E19: 4 | F19: =IF(OR(E19="",E19="UNKNOWN",E19="ERROR"),_xlfn.XLOOKUP(Table2[[#This Row],[Item]],Items_List!A:A,Items_List!B:B),E19) -> 4 | G19: 20 | H19: =D19*F19 -> 20 | I19: Cash | J19: In-store | K19: 45020 | L19: =IF(ISNUMBER(Table2[[#This Row],[Transaction Date]]),TEXT(Table2[[#This Row],[Transaction Date]],"mmmm"),"Unknown") -> April | M19: =IF(ISNUMBER(Table2[[#This Row],[Transaction Date]]),TEXT(Table2[[#This Row],[Transaction Date]],"dddd"),"Unknown") -> Tuesday | N19: =IF(OR(B19="",B19="unknown",B19="error",C19="",C19="unknown",C19="error",G19="",G19="error",G19="unknown"),1,0) -> 1 | O19: =IF(OR(C19="",C19="error",C19="unknown"),"Estimated","Actual") -> Estimated
A20: TXN_3567645 | B20: Smoothie | C20: 4 | D20: =IF(OR(C20="",C20="UNKNOWN",C20="ERROR"),IFERROR(VALUE(G20)/VALUE(E20),""),VALUE(C20)) -> 4 | E20: 4 | F20: =IF(OR(E20="",E20="UNKNOWN",E20="ERROR"),_xlfn.XLOOKUP(Table2[[#This Row],[Item]],Items_List!A:A,Items_List!B:B),E20) -> 4 | G20: 16 | H20: =D20*F20 -> 16 | I20: Credit Card | J20: Takeaway | K20: 45015 | L20: =IF(ISNUMBER(Table2[[#This Row],[Transaction Date]]),TEXT(Table2[[#This Row],[Transaction Date]],"mmmm"),"Unknown") -> March | M20: =IF(ISNUMBER(Table2[[#This Row],[Transaction Date]]),TEXT(Table2[[#This Row],[Transaction Date]],"dddd"),"Unknown") -> Thursday | N20: =IF(OR(B20="",B20="unknown",B20="error",C20="",C20="unknown",C20="error",G20="",G20="error",G20="unknown"),1,0) -> 0 | O20: =IF(OR(C20="",C20="error",C20="unknown"),"Estimated","Actual") -> Actual
A21: TXN_5132361 | B21: Sandwich | C21: 3 | D21: =IF(OR(C21="",C21="UNKNOWN",C21="ERROR"),IFERROR(VALUE(G21)/VALUE(E21),""),VALUE(C21)) -> 3 | E21: 4 | F21: =IF(OR(E21="",E21="UNKNOWN",E21="ERROR"),_xlfn.XLOOKUP(Table2[[#This Row],[Item]],Items_List!A:A,Items_List!B:B),E21) -> 4 | G21: 12 | H21: =D21*F21 -> 12 | I21: Digital Wallet | J21: Takeaway | K21: 45261 | L21: =IF(ISNUMBER(Table2[[#This Row],[Transaction Date]]),TEXT(Table2[[#This Row],[Transaction Date]],"mmmm"),"Unknown") -> December | M21: =IF(ISNUMBER(Table2[[#This Row],[Transaction Date]]),TEXT(Table2[[#This Row],[Transaction Date]],"dddd"),"Unknown") -> Friday | N21: =IF(OR(B21="",B21="unknown",B21="error",C21="",C21="unknown",C21="error",G21="",G21="error",G21="unknown"),1,0) -> 0 | O21: =IF(OR(C21="",C21="error",C21="unknown"),"Estimated","Actual") -> Actual
A22: TXN_2616390 | B22: Sandwich | C22: 2 | D22: =IF(OR(C22="",C22="UNKNOWN",C22="ERROR"),IFERROR(VALUE(G22)/VALUE(E22),""),VALUE(C22)) -> 2 | E22: 4 | F22: =IF(OR(E22="",E22="UNKNOWN",E22="ERROR"),_xlfn.XLOOKUP(Table2[[#This Row],[Item]],Items_List!A:A,Items_List!B:B),E22) -> 4 | G22: 8 | H22: =D22*F22 -> 8 | I22: N/A | J22: N/A | K22: 45187 | L22: =IF(ISNUMBER(Table2[[#This Row],[Transaction Date]]),TEXT(Table2[[#This Row],[Transaction Date]],"mmmm"),"Unknown") -> September | M22: =IF(ISNUMBER(Table2[[#This Row],[Transaction Date]]),TEXT(Table2[[#This Row],[Transaction Date]],"dddd"),"Unknown") -> Monday | N22: =IF(OR(B22="",B22="unknown",B22="error",C22="",C22="unknown",C22="error",G22="",G22="error",G22="unknown"),1,0) -> 0 | O22: =IF(OR(C22="",C22="error",C22="unknown"),"Estimated","Actual") -> Actual
A23: TXN_9400181 | B23: Sandwich | C23: 5 | D23: =IF(OR(C23="",C23="UNKNOWN",C23="ERROR"),IFERROR(VALUE(G23)/VALUE(E23),""),VALUE(C23)) -> 5 | E23: 4 | F23: =IF(OR(E23="",E23="UNKNOWN",E23="ERROR"),_xlfn.XLOOKUP(Table2[[#This Row],[Item]],Items_List!A:A,Items_List!B:B),E23) -> 4 | G23: 20 | H23: =D23*F23 -> 20 | I23: Cash | J23: In-store | K23: 45080 | L23: =IF(ISNUMBER(Table2[[#This Row],[Transaction Date]]),TEXT(Table2[[#This Row],[Transaction Date]],"mmmm"),"Unknown") -> June | M23: =IF(ISNUMBER(Table2[[#This Row],[Transaction Date]]),TEXT(Table2[[#This Row],[Transaction Date]],"dddd"),"Unknown") -> Saturday | N23: =IF(OR(B23="",B23="unknown",B23="error",C23="",C23="unknown",C23="error",G23="",G23="error",G23="unknown"),1,0) -> 0 | O23: =IF(OR(C23="",C23="error",C23="unknown"),"Estimated","Actual") -> Actual
A24: TXN_7958992 | B24: Smoothie | C24: 3 | D24: =IF(OR(C24="",C24="UNKNOWN",C24="ERROR"),IFERROR(VALUE(G24)/VALUE(E24),""),VALUE(C24)) -> 3 | E24: 4 | F24: =IF(OR(E24="",E24="UNKNOWN",E24="ERROR"),_xlfn.XLOOKUP(Table2[[#This Row],[Item]],Items_List!A:A,Items_List!B:B),E24) -> 4 | H24: =D24*F24 -> 12 | I24: N/A | J24: N/A | K24: 45273 | L24: =IF(ISNUMBER(Table2[[#This Row],[Transaction Date]]),TEXT(Table2[[#This Row],[Transaction Date]],"mmmm"),"Unknown") -> December | M24: =IF(ISNUMBER(Table2[[#This Row],[Transaction Date]]),TEXT(Table2[[#This Row],[Transaction Date]],"dddd"),"Unknown") -> Wednesday | N24: =IF(OR(B24="",B24="unknown",B24="error",C24="",C24="unknown",C24="error",G24="",G24="error",G24="unknown"),1,0) -> 1 | O24: =IF(OR(C24="",C24="error",C24="unknown"),"Estimated","Actual") -> Actual
A25: TXN_5183041 | B25: Cookie | C25: 5 | D25: =IF(OR(C25="",C25="UNKNOWN",C25="ERROR"),IFERROR(VALUE(G25)/VALUE(E25),""),VALUE(C25)) -> 5 | E25: 1 | F25: =IF(OR(E25="",E25="UNKNOWN",E25="ERROR"),_xlfn.XLOOKUP(Table2[[#This Row],[Item]],Items_List!A:A,Items_List!B:B),E25) -> 1 | G25: 5 | H25: =D25*F25 -> 5 | I25: Credit Card | J25: In-store | K25: 45036 | L25: =IF(ISNUMBER(Table2[[#This Row],[Transaction Date]]),TEXT(Table2[[#This Row],[Transaction Date]],"mmmm"),"Unknown") -> April | M25: =IF(ISNUMBER(Table2[[#This Row],[Transaction Date]]),TEXT(Table2[[#This Row],[Transaction Date]],"dddd"),"Unknown") -> Thursday | N25: =IF(OR(B25="",B25="unknown",B25="error",C25="",C25="unknown",C25="error",G25="",G25="error",G25="unknown"),1,0) -> 0 | O25: =IF(OR(C25="",C25="error",C25="unknown"),"Estimated","Actual") -> Actual
A26: TXN_5695074 | B26: Juice | C26: 4 | D26: =IF(OR(C26="",C26="UNKNOWN",C26="ERROR"),IFERROR(VALUE(G26)/VALUE(E26),""),VALUE(C26)) -> 4 | E26: 3 | F26: =IF(OR(E26="",E26="UNKNOWN",E26="ERROR"),_xlfn.XLOOKUP(Table2[[#This Row],[Item]],Items_List!A:A,Items_List!B:B),E26) -> 3 | G26: 12 | H26: =D26*F26 -> 12 | I26: Credit Card | J26: Takeaway | K26: 45026 | L26: =IF(ISNUMBER(Table2[[#This Row],[Transaction Date]]),TEXT(Table2[[#This Row],[Transaction Date]],"mmmm"),"Unknown") -> April | M26: =IF(ISNUMBER(Table2[[#This Row],[Transaction Date]]),TEXT(Table2[[#This Row],[Transaction Date]],"dddd"),"Unknown") -> Monday | N26: =IF(OR(B26="",B26="unknown",B26="error",C26="",C26="unknown",C26="error",G26="",G26="error",G26="unknown"),1,0) -> 0 | O26: =IF(OR(C26="",C26="error",C26="unknown"),"Estimated","Actual") -> Actual
A27: TXN_8467949 | B27: Smoothie | C27: 5 | D27: =IF(OR(C27="",C27="UNKNOWN",C27="ERROR"),IFERROR(VALUE(G27)/VALUE(E27),""),VALUE(C27)) -> 5 | E27: 4 | F27: =IF(OR(E27="",E27="UNKNOWN",E27="ERROR"),_xlfn.XLOOKUP(Table2[[#This Row],[Item]],Items_List!A:A,Items_List!B:B),E27) -> 4 | G27: 20 | H27: =D27*F27 -> 20 | I27: Credit Card | J27: N/A | K27: 44996 | L27: =IF(ISNUMBER(Table2[[#This Row],[Transaction Date]]),TEXT(Table2[[#This Row],[Transaction Date]],"mmmm"),"Unknown") -> March | M27: =IF(ISNUMBER(Table2[[#This Row],[Transaction Date]]),TEXT(Table2[[#This Row],[Transaction Date]],"dddd"),"Unknown") -> Saturday | N27: =IF(OR(B27="",B27="unknown",B27="error",C27="",C27="unknown",C27="error",G27="",G27="error",G27="unknown"),1,0) -> 0 | O27: =IF(OR(C27="",C27="error",C27="unknown"),"Estimated","Actual") -> Actual
A28: TXN_7640952 | B28: Cake | C28: 4 | D28: =IF(OR(C28="",C28="UNKNOWN",C28="ERROR"),IFERROR(VALUE(G28)/VALUE(E28),""),VALUE(C28)) -> 4 | E28: 3 | F28: =IF(OR(E28="",E28="UNKNOWN",E28="ERROR"),_xlfn.XLOOKUP(Table2[[#This Row],[Item]],Items_List!A:A,Items_List!B:B),E28) -> 3 | G28: 12 | H28: =D28*F28 -> 12 | I28: Digital Wallet | J28: Takeaway | L28: =IF(ISNUMBER(Table2[[#This Row],[Transaction Date]]),TEXT(Table2[[#This Row],[Transaction Date]],"mmmm"),"Unknown") -> Unknown | M28: =IF(ISNUMBER(Table2[[#This Row],[Transaction Date]]),TEXT(Table2[[#This Row],[Transaction Date]],"dddd"),"Unknown") -> Unknown | N28: =IF(OR(B28="",B28="unknown",B28="error",C28="",C28="unknown",C28="error",G28="",G28="error",G28="unknown"),1,0) -> 0 | O28: =IF(OR(C28="",C28="error",C28="unknown"),"Estimated","Actual") -> Actual
A29: TXN_9677376 | B29: Smoothie | C29: 4 | D29: =IF(OR(C29="",C29="UNKNOWN",C29="ERROR"),IFERROR(VALUE(G29)/VALUE(E29),""),VALUE(C29)) -> 4 | E29: 4 | F29: =IF(OR(E29="",E29="UNKNOWN",E29="ERROR"),_xlfn.XLOOKUP(Table2[[#This Row],[Item]],Items_List!A:A,Items_List!B:B),E29) -> 4 | G29: 16 | H29: =D29*F29 -> 16 | I29: N/A | J29: In-store | K29: 45153 | L29: =IF(ISNUMBER(Table2[[#This Row],[Transaction Date]]),TEXT(Table2[[#This Row],[Transaction Date]],"mmmm"),"Unknown") -> August | M29: =IF(ISNUMBER(Table2[[#This Row],[Transaction Date]]),TEXT(Table2[[#This Row],[Transaction Date]],"dddd"),"Unknown") -> Tuesday | N29: =IF(OR(B29="",B29="unknown",B29="error",C29="",C29="unknown",C29="error",G29="",G29="error",G29="unknown"),1,0) -> 0 | O29: =IF(OR(C29="",C29="error",C29="unknown"),"Estimated","Actual") -> Actual
A30: TXN_8853997 | B30: Smoothie | C30: 2 | D30: =IF(OR(C30="",C30="UNKNOWN",C30="ERROR"),IFERROR(VALUE(G30)/VALUE(E30),""),VALUE(C30)) -> 2 | E30: 4 | F30: =IF(OR(E30="",E30="UNKNOWN",E30="ERROR"),_xlfn.XLOOKUP(Table2[[#This Row],[Item]],Items_List!A:A,Items_List!B:B),E30) -> 4 | G30: 8 | H30: =D30*F30 -> 8 | I30: Digital Wallet | J30: Takeaway | K30: 45208 | L30: =IF(ISNUMBER(Table2[[#This Row],[Transaction Date]]),TEXT(Table2[[#This Row],[Transaction Date]],"mmmm"),"Unknown") -> October | M30: =IF(ISNUMBER(Table2[[#This Row],[Transaction Date]]),TEXT(Table2[[#This Row],[Transaction Date]],"dddd"),"Unknown") -> Monday | N30: =IF(OR(B30="",B30="unknown",B30="error",C30="",C30="unknown",C30="error",G30="",G30="error",G30="unknown"),1,0) -> 0 | O30: =IF(OR(C30="",C30="error",C30="unknown"),"Estimated","Actual") -> Actual
A31: TXN_9130559 | B31: Sandwich | C31: 1 | D31: =IF(OR(C31="",C31="UNKNOWN",C31="ERROR"),IFERROR(VALUE(G31)/VALUE(E31),""),VALUE(C31)) -> 1 | E31: 4 | F31: =IF(OR(E31="",E31="UNKNOWN",E31="ERROR"),_xlfn.XLOOKUP(Table2[[#This Row],[Item]],Items_List!A:A,Items_List!B:B),E31) -> 4 | G31: 4 | H31: =D31*F31 -> 4 | I31: Credit Card | J31: N/A | K31: 45074 | L31: =IF(ISNUMBER(Table2[[#This Row],[Transaction Date]]),TEXT(Table2[[#This Row],[Transaction Date]],"mmmm"),"Unknown") -> May | M31: =IF(ISNUMBER(Table2[[#This Row],[Transaction Date]]),TEXT(Table2[[#This Row],[Transaction Date]],"dddd"),"Unknown") -> Sunday | N31: =IF(OR(B31="",B31="unknown",B31="error",C31="",C31="unknown",C31="error",G31="",G31="error",G31="unknown"),1,0) -> 0 | O31: =IF(OR(C31="",C31="error",C31="unknown"),"Estimated","Actual") -> Actual
A32: TXN_1080432 | B32: Salad | C32: 2 | D32: =IF(OR(C32="",C32="UNKNOWN",C32="ERROR"),IFERROR(VALUE(G32)/VALUE(E32),""),VALUE(C32)) -> 2 | E32: 5 | F32: =IF(OR(E32="",E32="UNKNOWN",E32="ERROR"),_xlfn.XLOOKUP(Table2[[#This Row],[Item]],Items_List!A:A,Items_List!B:B),E32) -> 5 | G32: 10 | H32: =D32*F32 -> 10 | I32: Credit Card | J32: In-store | K32: 45045 | L32: =IF(ISNUMBER(Table2[[#This Row],[Transaction Date]]),TEXT(Table2[[#This Row],[Transaction Date]],"mmmm"),"Unknown") -> April | M32: =IF(ISNUMBER(Table2[[#This Row],[Transaction Date]]),TEXT(Table2[[#This Row],[Transaction Date]],"dddd"),"Unknown") -> Saturday | N32: =IF(OR(B32="",B32="unknown",B32="error",C32="",C32="unknown",C32="error",G32="",G32="error",G32="unknown"),1,0) -> 0 | O32: =IF(OR(C32="",C32="error",C32="unknown"),"Estimated","Actual") -> Actual
A33: TXN_2655815 | B33: Smoothie | C33: 4 | D33: =IF(OR(C33="",C33="UNKNOWN",C33="ERROR"),IFERROR(VALUE(G33)/VALUE(E33),""),VALUE(C33)) -> 4 | E33: 4 | F33: =IF(OR(E33="",E33="UNKNOWN",E33="ERROR"),_xlfn.XLOOKUP(Table2[[#This Row],[Item]],Items_List!A:A,Items_List!B:B),E33) -> 4 | G33: 16 | H33: =D33*F33 -> 16 | I33: N/A | J33: Takeaway | K33: 45085 | L33: =IF(ISNUMBER(Table2[[#This Row],[Transaction Date]]),TEXT(Table2[[#This Row],[Transaction Date]],"mmmm"),"Unknown") -> June | M33: =IF(ISNUMBER(Table2[[#This Row],[Transaction Date]]),TEXT(Table2[[#This Row],[Transaction Date]],"dddd"),"Unknown") -> Thursday | N33: =IF(OR(B33="",B33="unknown",B33="error",C33="",C33="unknown",C33="error",G33="",G33="error",G33="unknown"),1,0) -> 0 | O33: =IF(OR(C33="",C33="error",C33="unknown"),"Estimated","Actual") -> Actual
A34: TXN_6688524 | B34: Coffee | C34: 4 | D34: =IF(OR(C34="",C34="UNKNOWN",C34="ERROR"),IFERROR(VALUE(G34)/VALUE(E34),""),VALUE(C34)) -> 4 | E34: 2 | F34: =IF(OR(E34="",E34="UNKNOWN",E34="ERROR"),_xlfn.XLOOKUP(Table2[[#This Row],[Item]],Items_List!A:A,Items_List!B:B),E34) -> 2 | G34: 8 | H34: =D34*F34 -> 8 | I34: N/A | J34: N/A | K34: 45106 | L34: =IF(ISNUMBER(Table2[[#This Row],[Transaction Date]]),TEXT(Table2[[#This Row],[Transaction Date]],"mmmm"),"Unknown") -> June | M34: =IF(ISNUMBER(Table2[[#This Row],[Transaction Date]]),TEXT(Table2[[#This Row],[Transaction Date]],"dddd"),"Unknown") -> Thursday | N34: =IF(OR(B34="",B34="unknown",B34="error",C34="",C34="unknown",C34="error",G34="",G34="error",G34="unknown"),1,0) -> 0 | O34: =IF(OR(C34="",C34="error",C34="unknown"),"Estimated","Actual") -> Actual
A35: TXN_2083138 | B35: Smoothie | C35: 3 | D35: =IF(OR(C35="",C35="UNKNOWN",C35="ERROR"),IFERROR(VALUE(G35)/VALUE(E35),""),VALUE(C35)) -> 3 | E35: 4 | F35: =IF(OR(E35="",E35="UNKNOWN",E35="ERROR"),_xlfn.XLOOKUP(Table2[[#This Row],[Item]],Items_List!A:A,Items_List!B:B),E35) -> 4 | G35: 12 | H35: =D35*F35 -> 12 | I35: N/A | J35: In-store | K35: 45033 | L35: =IF(ISNUMBER(Table2[[#This Row],[Transaction Date]]),TEXT(Table2[[#This Row],[Transaction Date]],"mmmm"),"Unknown") -> April | M35: =IF(ISNUMBER(Table2[[#This Row],[Transaction Date]]),TEXT(Table2[[#This Row],[Transaction Date]],"dddd"),"Unknown") -> Monday | N35: =IF(OR(B35="",B35="unknown",B35="error",C35="",C35="unknown",C35="error",G35="",G35="error",G35="unknown"),1,0) -> 0 | O35: =IF(OR(C35="",C35="error",C35="unknown"),"Estimated","Actual") -> Actual
A36: TXN_2427584 | B36: Sandwich | C36: 4 | D36: =IF(OR(C36="",C36="UNKNOWN",C36="ERROR"),IFERROR(VALUE(G36)/VALUE(E36),""),VALUE(C36)) -> 4 | E36: 4 | F36: =IF(OR(E36="",E36="UNKNOWN",E36="ERROR"),_xlfn.XLOOKUP(Table2[[#This Row],[Item]],Items_List!A:A,Items_List!B:B),E36) -> 4 | G36: 16 | H36: =D36*F36 -> 16 | I36: N/A | J36: Takeaway | K36: 45282 | L36: =IF(ISNUMBER(Table2[[#This Row],[Transaction Date]]),TEXT(Table2[[#This Row],[Transaction Date]],"mmmm"),"Unknown") -> December | M36: =IF(ISNUMBER(Table2[[#This Row],[Transaction Date]]),TEXT(Table2[[#This Row],[Transaction Date]],"dddd"),"Unknown") -> Friday | N36: =IF(OR(B36="",B36="unknown",B36="error",C36="",C36="unknown",C36="error",G36="",G36="error",G36="unknown"),1,0) -> 0 | O36: =IF(OR(C36="",C36="error",C36="unknown"),"Estimated","Actual") -> Actual
A37: TXN_6650263 | B37: Tea | C37: 2 | D37: =IF(OR(C37="",C37="UNKNOWN",C37="ERROR"),IFERROR(VALUE(G37)/VALUE(E37),""),VALUE(C37)) -> 2 | E37: 1.5 | F37: =IF(OR(E37="",E37="UNKNOWN",E37="ERROR"),_xlfn.XLOOKUP(Table2[[#This Row],[Item]],Items_List!A:A,Items_List!B:B),E37) -> 1.5 | G37: UNKNOWN | H37: =D37*F37 -> 3 | I37: N/A | J37: Takeaway | K37: 44936 | L37: =IF(ISNUMBER(Table2[[#This Row],[Transaction Date]]),TEXT(Table2[[#This Row],[Transaction Date]],"mmmm"),"Unknown") -> January | M37: =IF(ISNUMBER(Table2[[#This Row],[Transaction Date]]),TEXT(Table2[[#This Row],[Transaction Date]],"dddd"),"Unknown") -> Tuesday | N37: =IF(OR(B37="",B37="unknown",B37="error",C37="",C37="unknown",C37="error",G37="",G37="error",G37="unknown"),1,0) -> 1 | O37: =IF(OR(C37="",C37="error",C37="unknown"),"Estimated","Actual") -> Actual
A38: TXN_9620080 | B38: Juice | C38: 4 | D38: =IF(OR(C38="",C38="UNKNOWN",C38="ERROR"),IFERROR(VALUE(G38)/VALUE(E38),""),VALUE(C38)) -> 4 | E38: 3 | F38: =IF(OR(E38="",E38="UNKNOWN",E38="ERROR"),_xlfn.XLOOKUP(Table2[[#This Row],[Item]],Items_List!A:A,Items_List!B:B),E38) -> 3 | G38: 12 | H38: =D38*F38 -> 12 | I38: N/A | J38: Takeaway | K38: 45201 | L38: =IF(ISNUMBER(Table2[[#This Row],[Transaction Date]]),TEXT(Table2[[#This Row],[Transaction Date]],"mmmm"),"Unknown") -> October | M38: =IF(ISNUMBER(Table2[[#This Row],[Transaction Date]]),TEXT(Table2[[#This Row],[Transaction Date]],"dddd"),"Unknown") -> Monday | N38: =IF(OR(B38="",B38="unknown",B38="error",C38="",C38="unknown",C38="error",G38="",G38="error",G38="unknown"),1,0) -> 0 | O38: =IF(OR(C38="",C38="error",C38="unknown"),"Estimated","Actual") -> Actual
A39: TXN_1491578 | B39: Cookie | C39: 2 | D39: =IF(OR(C39="",C39="UNKNOWN",C39="ERROR"),IFERROR(VALUE(G39)/VALUE(E39),""),VALUE(C39)) -> 2 | E39: 1 | F39: =IF(OR(E39="",E39="UNKNOWN",E39="ERROR"),_xlfn.XLOOKUP(Table2[[#This Row],[Item]],Items_List!A:A,Items_List!B:B),E39) -> 1 | G39: 2 | H39: =D39*F39 -> 2 | I39: N/A | J39: N/A | K39: 44980 | L39: =IF(ISNUMBER(Table2[[#This Row],[Transaction Date]]),TEXT(Table2[[#This Row],[Transaction Date]],"mmmm"),"Unknown") -> February | M39: =IF(ISNUMBER(Table2[[#This Row],[Transaction Date]]),TEXT(Table2[[#This Row],[Transaction Date]],"dddd"),"Unknown") -> Thursday | N39: =IF(OR(B39="",B39="unknown",B39="error",C39="",C39="unknown",C39="error",G39="",G39="error",G39="unknown"),1,0) -> 0 | O39: =IF(OR(C39="",C39="error",C39="unknown"),"Estimated","Actual") -> Actual
A40: TXN_5455792 | B40: Salad | C40: 3 | D40: =IF(OR(C40="",C40="UNKNOWN",C40="ERROR"),IFERROR(VALUE(G40)/VALUE(E40),""),VALUE(C40)) -> 3 | E40: 5 | F40: =IF(OR(E40="",E40="UNKNOWN",E40="ERROR"),_xlfn.XLOOKUP(Table2[[#This Row],[Item]],Items_List!A:A,Items_List!B:B),E40) -> 5 | G40: 15 | H40: =D40*F40 -> 15 | I40: Cash | J40: N/A | K40: 45007 | L40: =IF(ISNUMBER(Table2[[#This Row],[Transaction Date]]),TEXT(Table2[[#This Row],[Transaction Date]],"mmmm"),"Unknown") -> March | M40: =IF(ISNUMBER(Table2[[#This Row],[Transaction Date]]),TEXT(Table2[[#This Row],[Transaction Date]],"dddd"),"Unknown") -> Wednesday | N40: =IF(OR(B40="",B40="unknown",B40="error",C40="",C40="unknown",C40="error",G40="",G40="error",G40="unknown"),1,0) -> 0 | O40: =IF(OR(C40="",C40="error",C40="unknown"),"Estimated","Actual") -> Actual
...

Sheet Items_List
A1: Item | B1: Price
A2: Coffee | B2: 2
A3: Cake | B3: 3
A4: Salad | B4: 5
A5: Cookie | B5: 1
A6: Smoothie | B6: 4
A7: Sandwich | B7: 4
A8: Juice | B8: 3
A9: Tea | B9: 1.5

Sheet dirty_cafe_sales
A1: Transaction ID | B1: Item | C1: Quantity | D1: Price Per Unit | E1: Total Spent | F1: Payment Method | G1: Location | H1: Transaction Date
A2: TXN_1961373 | B2: Coffee | C2: 2 | D2: 2 | E2: 4 | F2: Credit Card | G2: Takeaway | H2: 45177
A3: TXN_4977031 | B3: Cake | C3: 4 | D3: 3 | E3: 12 | F3: Cash | G3: In-store | H3: 45062
A4: TXN_4271903 | B4: Cookie | C4: 4 | D4: 1 | E4: ERROR | F4: Credit Card | G4: In-store | H4: 45126
A5: TXN_7034554 | B5: Salad | C5: 2 | D5: 5 | E5: 10 | F5: UNKNOWN | G5: UNKNOWN | H5: 45043
A6: TXN_3160411 | B6: Coffee | C6: 2 | D6: 2 | E6: 4 | F6: Digital Wallet | G6: In-store | H6: 45088
A7: TXN_2602893 | B7: Smoothie | C7: 5 | D7: 4 | E7: 20 | F7: Credit Card | H7: 45016
A8: TXN_4433211 | B8: UNKNOWN | C8: 3 | D8: 3 | E8: 9 | F8: ERROR | G8: Takeaway | H8: 45205
A9: TXN_6699534 | B9: Sandwich | C9: 4 | D9: 4 | E9: 16 | F9: Cash | G9: UNKNOWN | H9: 45227
A10: TXN_4717867 | C10: 5 | D10: 3 | E10: 15 | G10: Takeaway | H10: 45135
A11: TXN_2064365 | B11: Sandwich | C11: 5 | D11: 4 | E11: 20 | G11: In-store | H11: 45291
A12: TXN_2548360 | B12: Salad | C12: 5 | D12: 5 | E12: 25 | F12: Cash | G12: Takeaway | H12: 45237
A13: TXN_3051279 | B13: Sandwich | C13: 2 | D13: 4 | E13: 8 | F13: Credit Card | G13: Takeaway | H13: ERROR
A14: TXN_7619095 | B14: Sandwich | C14: 2 | D14: 4 | E14: 8 | F14: Cash | G14: In-store | H14: 45049
A15: TXN_9437049 | B15: Cookie | C15: 5 | D15: 1 | E15: 5 | G15: Takeaway | H15: 45078
A16: TXN_8915701 | B16: ERROR | C16: 2 | D16: 1.5 | E16: 3 | G16: In-store | H16: 45006
A17: TXN_2847255 | B17: Salad | C17: 3 | D17: 5 | E17: 15 | F17: Credit Card | G17: In-store | H17: 45245
A18: TXN_3765707 | B18: Sandwich | C18: 1 | D18: 4 | E18: 4 | H18: 45087
A19: TXN_6769710 | B19: Juice | C19: 2 | D19: 3 | E19: 6 | F19: Cash | G19: In-store | H19: 44981
A20: TXN_8876618 | B20: Cake | C20: 5 | D20: 3 | E20: 15 | F20: Cash | G20: ERROR | H20: 45010
A21: TXN_3709394 | B21: Juice | C21: 4 | D21: 3 | E21: 12 | F21: Cash | G21: Takeaway | H21: 44941
A22: TXN_3522028 | B22: Smoothie | C22: ERROR | D22: 4 | E22: 20 | F22: Cash | G22: In-store | H22: 45020
A23: TXN_3567645 | B23: Smoothie | C23: 4 | D23: 4 | E23: 16 | F23: Credit Card | G23: Takeaway | H23: 45015
A24: TXN_5132361 | B24: Sandwich | C24: 3 | D24: 4 | E24: 12 | F24: Digital Wallet | G24: Takeaway | H24: 45261
A25: TXN_2616390 | B25: Sandwich | C25: 2 | D25: 4 | E25: 8 | H25: 45187
A26: TXN_9400181 | B26: Sandwich | C26: 5 | D26: 4 | E26: 20 | F26: Cash | G26: In-store | H26: 45080
A27: TXN_7958992 | B27: Smoothie | C27: 3 | D27: 4 | F27: UNKNOWN | G27: UNKNOWN | H27: 45273
A28: TXN_5183041 | B28: Cookie | C28: 5 | D28: 1 | E28: 5 | F28: Credit Card | G28: In-store | H28: 45036
A29: TXN_5695074 | B29: Juice | C29: 4 | D29: 3 | E29: 12 | F29: Credit Card | G29: Takeaway | H29: 45026
A30: TXN_8467949 | B30: Smoothie | C30: 5 | D30: 4 | E30: 20 | F30: Credit Card | H30: 44996
A31: TXN_7640952 | B31: Cake | C31: 4 | D31: 3 | E31: 12 | F31: Digital Wallet | G31: Takeaway | H31: ERROR
A32: TXN_1736287 | C32: 5 | D32: 2 | E32: 10 | F32: Digital Wallet | H32: 45079
A33: TXN_8927252 | B33: UNKNOWN | C33: 2 | D33: 1 | E33: ERROR | F33: Credit Card | G33: ERROR | H33: 45236
A34: TXN_9677376 | B34: Smoothie | C34: 4 | D34: 4 | E34: 16 | G34: In-store | H34: 45153
A35: TXN_7710508 | B35: UNKNOWN | C35: 5 | D35: 1 | E35: 5 | F35: Cash | H35: ERROR
A36: TXN_8853997 | B36: Smoothie | C36: 2 | D36: 4 | E36: 8 | F36: Digital Wallet | G36: Takeaway | H36: 45208
A37: TXN_9130559 | B37: Sandwich | C37: 1 | D37: 4 | E37: 4 | F37: Credit Card | G37: UNKNOWN | H37: 45074
A38: TXN_6855453 | B38: UNKNOWN | C38: 4 | D38: 3 | E38: 12 | G38: In-store | H38: 45124
A39: TXN_1080432 | B39: Salad | C39: 2 | D39: 5 | E39: 10 | F39: Credit Card | G39: In-store | H39: 45045
A40: TXN_2655815 | B40: Smoothie | C40: 4 | D40: 4 | E40: 16 | G40: Takeaway | H40: 45085
...
